Traceback (most recent call last):
  File "/Users/caiazzo/opt/anaconda3/lib/python3.7/site-packages/jupyter_cache/executors/utils.py", line 56, in single_nb_execution
    record_timing=False,
  File "/Users/caiazzo/opt/anaconda3/lib/python3.7/site-packages/nbclient/client.py", line 1087, in execute
    return NotebookClient(nb=nb, resources=resources, km=km, **kwargs).execute()
  File "/Users/caiazzo/opt/anaconda3/lib/python3.7/site-packages/nbclient/util.py", line 74, in wrapped
    return just_run(coro(*args, **kwargs))
  File "/Users/caiazzo/opt/anaconda3/lib/python3.7/site-packages/nbclient/util.py", line 53, in just_run
    return loop.run_until_complete(coro)
  File "/Users/caiazzo/opt/anaconda3/lib/python3.7/asyncio/base_events.py", line 583, in run_until_complete
    return future.result()
  File "/Users/caiazzo/opt/anaconda3/lib/python3.7/site-packages/nbclient/client.py", line 541, in async_execute
    cell, index, execution_count=self.code_cells_executed + 1
  File "/Users/caiazzo/opt/anaconda3/lib/python3.7/site-packages/nbclient/client.py", line 832, in async_execute_cell
    self._check_raise_for_error(cell, exec_reply)
  File "/Users/caiazzo/opt/anaconda3/lib/python3.7/site-packages/nbclient/client.py", line 740, in _check_raise_for_error
    raise CellExecutionError.from_cell_and_msg(cell, exec_reply['content'])
nbclient.exceptions.CellExecutionError: An error occurred while executing the following cell:
------------------
import os,sys, folium, pandas
HIT_PATH = '../../../HIT/src/' # local path to HIT src code
sys.path.insert(0, os.path.normpath(os.path.join(os.path.abspath(''), HIT_PATH)))
import hedera_types as hedera
import odk_interface as odk

import matplotlib.pyplot as plt

import matplotlib.font_manager as fm
fontpath = '/Library/Fonts/JosefinSans-Regular.ttf'
fm.fontManager.addfont(fontpath)
prop = fm.FontProperties(fname=fontpath)

# change plot layout
plt.rcParams["font.family"] = prop.get_name()
plt.rcParams.update({'font.size': 18})
odk_data_dir = '../../../ODK_Collect_Data/Hillary_Kenya/'


odk_folder_dir = 'HEDERA_SDG7/'
#odk_folder_dir = 'HEDERA_SDG7_19_07_05/'
## @brief name of the file (this should not be changed, it is set from ODK)
odk_data_name = 'HEDERA_SDG7_results.csv'

# initialize the institution
mfi = hedera.mfi(4)

# read database
data = mfi.read_survey(odk_data_dir+odk_folder_dir+odk_data_name,
                           delimiter='-')
mfi.HH = odk.households(data)
collection_overview = odk.overview(mfi.HH,mfi)
------------------

[0;31m---------------------------------------------------------------------------[0m
[0;31mModuleNotFoundError[0m                       Traceback (most recent call last)
[0;32m<ipython-input-1-5c0fe0d4193f>[0m in [0;36m<module>[0;34m[0m
[1;32m      2[0m [0mHIT_PATH[0m [0;34m=[0m [0;34m'../../../HIT/src/'[0m [0;31m# local path to HIT src code[0m[0;34m[0m[0;34m[0m[0m
[1;32m      3[0m [0msys[0m[0;34m.[0m[0mpath[0m[0;34m.[0m[0minsert[0m[0;34m([0m[0;36m0[0m[0;34m,[0m [0mos[0m[0;34m.[0m[0mpath[0m[0;34m.[0m[0mnormpath[0m[0;34m([0m[0mos[0m[0;34m.[0m[0mpath[0m[0;34m.[0m[0mjoin[0m[0;34m([0m[0mos[0m[0;34m.[0m[0mpath[0m[0;34m.[0m[0mabspath[0m[0;34m([0m[0;34m''[0m[0;34m)[0m[0;34m,[0m [0mHIT_PATH[0m[0;34m)[0m[0;34m)[0m[0;34m)[0m[0;34m[0m[0;34m[0m[0m
[0;32m----> 4[0;31m [0;32mimport[0m [0mhedera_types[0m [0;32mas[0m [0mhedera[0m[0;34m[0m[0;34m[0m[0m
[0m[1;32m      5[0m [0;32mimport[0m [0modk_interface[0m [0;32mas[0m [0modk[0m[0;34m[0m[0;34m[0m[0m
[1;32m      6[0m [0;34m[0m[0m

[0;31mModuleNotFoundError[0m: No module named 'hedera_types'
ModuleNotFoundError: No module named 'hedera_types'

